Workbook
Name UPDATE: 'Data Sheet'!$E$1

Sheet Data Sheet
A1: COMPANY NAME | B1: INFOSYS LTD | E1: =IF(B2<>B3, "A NEW VERSION OF THE WORKSHEET IS AVAILABLE", "")
A2: LATEST VERSION | B2: 2.1 | E2: PLEASE DO NOT MAKE ANY CHANGES TO THIS SHEET
A3: CURRENT VERSION | B3: 2.1
A5: META
A6: Number of shares | B6: =IF(B9>0, B9/B8, 0) -> 405.81468
A7: Face Value | B7: 5
A8: Current Price | B8: 1069.3
A9: Market Capitalization | B9: 433937.64
A15: PROFIT & LOSS
A16: Report Date | B16: 42825 | C16: 43190 | D16: 43555 | E16: 43921 | F16: 44286 | G16: 44651 | H16: 45016 | I16: 45382 | J16: 45747 | K16: 46112
A17: Sales | B17: 68484 | C17: 70522 | D17: 82675 | E17: 90791 | F17: 100472 | G17: 121641 | H17: 146767 | I17: 153670 | J17: 162990 | K17: 178650
A18: Raw Material Cost
A19: Change in Inventory
A20: Power and Fuel | B20: 228 | C20: 207 | D20: 221 | E20: 229 | F20: 143 | G20: 132 | H20: 176 | I20: 199 | J20: 222 | K20: 223
A21: Other Mfr. Exp | B21: 6712 | C21: 7286 | D21: 9902 | E21: 11086 | F21: 12800 | G21: 20690 | H21: 26330 | I21: 27195 | J21: 30395 | K21: 32922
A22: Employee Cost | B22: 37669 | C22: 38902 | D22: 45323 | E22: 50895 | F22: 55547 | G22: 63997 | H22: 78374 | I22: 82636 | J22: 85968 | K22: 95112
A23: Selling and admin | B23: 4584 | C23: 4585 | D23: 5553 | E23: 5375 | F23: 3194 | G23: 4305 | H23: 5300 | I23: 5705 | J23: 6039 | K23: 6784
A24: Other Expenses | B24: 687 | C24: 720 | D24: 1506 | E24: 939 | F24: 899 | G24: 1026 | H24: 1457 | I24: 1510 | J24: 1130 | K24: 1329
A25: Other Income | B25: 3050 | C25: 3311 | D25: 2882 | E25: 2803 | F25: 2201 | G25: 2295 | H25: 2701 | I25: 4711 | J25: 3600 | K25: 3033
A26: Depreciation | B26: 1703 | C26: 1863 | D26: 2011 | E26: 2893 | F26: 3267 | G26: 3476 | H26: 4225 | I26: 4678 | J26: 4812 | K26: 4902
A27: Interest | E27: 170 | F27: 195 | G27: 200 | H27: 284 | I27: 470 | J27: 416 | K27: 416
A28: Profit before tax | B28: 19951 | C28: 20270 | D28: 21041 | E28: 22007 | F28: 26628 | G28: 30110 | H28: 33322 | I28: 35988 | J28: 37608 | K28: 39995
A29: Tax | B29: 5598 | C29: 4241 | D29: 5631 | E29: 5368 | F29: 7205 | G29: 7964 | H29: 9214 | I29: 9740 | J29: 10858 | K29: 10521
A30: Net profit | B30: 14353 | C30: 16029 | D30: 15404 | E30: 16594 | F30: 19351 | G30: 22110 | H30: 24095 | I30: 26233 | J30: 26713 | K30: 29440
A31: Dividend Amount | B31: 5891.6 | C31: 9465.6 | D31: 9222.5 | E31: 7427 | F31: 11469.6 | G31: 13007.6 | H31: 14069.2 | I31: 19053.2 | J31: 17827.8 | K31: 19430.4
A40: Quarters
A41: Report Date | B41: 45291 | C41: 45382 | D41: 45473 | E41: 45565 | F41: 45657 | G41: 45747 | H41: 45838 | I41: 45930 | J41: 46022 | K41: 46112
A42: Sales | B42: 38821 | C42: 37923 | D42: 39315 | E42: 40986 | F42: 41764 | G42: 40925 | H42: 42279 | I42: 44490 | J42: 45479 | K42: 46402
A43: Expenses | B43: 29684 | C43: 29139 | D43: 29878 | E43: 31177 | F43: 31649 | G43: 31051 | H43: 32336 | I43: 33955 | J43: 34845 | K43: 35235
A44: Other Income | B44: 789 | C44: 2729 | D44: 838 | E44: 712 | F44: 859 | G44: 1190 | H44: 1042 | I44: 982 | J44: -150 | K44: 1159
A45: Depreciation | B45: 1176 | C45: 1163 | D45: 1149 | E45: 1160 | F45: 1203 | G45: 1299 | H45: 1140 | I45: 1182 | J45: 1155 | K45: 1424
A46: Interest | B46: 131 | C46: 110 | D46: 105 | E46: 108 | F46: 101 | G46: 102 | H46: 105 | I46: 106 | J46: 100 | K46: 105
A47: Profit before tax | B47: 8619 | C47: 10240 | D47: 9021 | E47: 9253 | F47: 9670 | G47: 9663 | H47: 9740 | I47: 10229 | J47: 9229 | K47: 10797
A48: Tax | B48: 2506 | C48: 2265 | D48: 2647 | E48: 2737 | F48: 2848 | G48: 2625 | H48: 2816 | I48: 2854 | J48: 2563 | K48: 2288
A49: Net profit | B49: 6106 | C49: 7969 | D49: 6368 | E49: 6506 | F49: 6806 | G49: 7033 | H49: 6921 | I49: 7364 | J49: 6654 | K49: 8501
A50: Operating Profit | B50: 9137 | C50: 8784 | D50: 9437 | E50: 9809 | F50: 10115 | G50: 9874 | H50: 9943 | I50: 10535 | J50: 10634 | K50: 11167
A55: BALANCE SHEET
A56: Report Date | B56: 42825 | C56: 43190 | D56: 43555 | E56: 43921 | F56: 44286 | G56: 44651 | H56: 45016 | I56: 45382 | J56: 45747 | K56: 46112
A57: Equity Share Capital | B57: 1144 | C57: 1088 | D57: 2170 | E57: 2122 | F57: 2124 | G57: 2098 | H57: 2069 | I57: 2071 | J57: 2073 | K57: 2024
A58: Reserves | B58: 67838 | C58: 63835 | D58: 62778 | E58: 63328 | F58: 74227 | G58: 73252 | H58: 73338 | I58: 86045 | J58: 93745 | K58: 90828
...

Sheet HistoricalFS
B2: ="Historical Financial Statement-"&'Data Sheet'!B1 -> Historical Financial Statement-INFOSYS LTD
B3: Years | C3: ='Data Sheet'!B16 -> 42825 | D3: ='Data Sheet'!C16 -> 43190 | E3: ='Data Sheet'!D16 -> 43555 | F3: ='Data Sheet'!E16 -> 43921 | G3: ='Data Sheet'!F16 -> 44286 | H3: ='Data Sheet'!G16 -> 44651 | I3: ='Data Sheet'!H16 -> 45016 | J3: ='Data Sheet'!I16 -> 45382 | ... L3: ='Data Sheet'!K16 -> 46112 | M3: LTM
A4: # | B4: Income Statement
B5: Sales | C5: =IFERROR('Data Sheet'!B17,0) -> 68484 | D5: =IFERROR('Data Sheet'!C17,0) -> 70522 | E5: =IFERROR('Data Sheet'!D17,0) -> 82675 | F5: =IFERROR('Data Sheet'!E17,0) -> 90791 | G5: =IFERROR('Data Sheet'!F17,0) -> 100472 | H5: =IFERROR('Data Sheet'!G17,0) -> 121641 | I5: =IFERROR('Data Sheet'!H17,0) -> 146767 | J5: =IFERROR('Data Sheet'!I17,0) -> 153670 | ... L5: =IFERROR('Data Sheet'!K17,0) -> 178650 | M5: =IFERROR(SUM('Data Sheet'!H42:K42),0) -> 178650
B6: Sales Growth% | D6: =IFERROR(D5/C5-1,0) -> 0.029758776 | E6: =IFERROR(E5/D5-1,0) -> 0.1723292 | F6: =IFERROR(F5/E5-1,0) -> 0.098167523 | G6: =IFERROR(G5/F5-1,0) -> 0.10662951 | H6: =IFERROR(H5/G5-1,0) -> 0.21069552 | I6: =IFERROR(I5/H5-1,0) -> 0.20655864 | J6: =IFERROR(J5/I5-1,0) -> 0.047033734 | K6: =IFERROR(K5/J5-1,0) -> 0.060649444 | ... M6: =IFERROR(M5/L5-1,0) -> 0
B8: COGS | C8: =IFERROR(SUM('Data Sheet'!B18,'Data Sheet'!B20:B22)-1*'Data Sheet'!B19,0) -> 44609 | D8: =IFERROR(SUM('Data Sheet'!C18,'Data Sheet'!C20:C22)-1*'Data Sheet'!C19,0) -> 46395 | E8: =IFERROR(SUM('Data Sheet'!D18,'Data Sheet'!D20:D22)-1*'Data Sheet'!D19,0) -> 55446 | F8: =IFERROR(SUM('Data Sheet'!E18,'Data Sheet'!E20:E22)-1*'Data Sheet'!E19,0) -> 62210 | G8: =IFERROR(SUM('Data Sheet'!F18,'Data Sheet'!F20:F22)-1*'Data Sheet'!F19,0) -> 68490 | H8: =IFERROR(SUM('Data Sheet'!G18,'Data Sheet'!G20:G22)-1*'Data Sheet'!G19,0) -> 84819 | I8: =IFERROR(SUM('Data Sheet'!H18,'Data Sheet'!H20:H22)-1*'Data Sheet'!H19,0) -> 104880 | J8: =IFERROR(SUM('Data Sheet'!I18,'Data Sheet'!I20:I22)-1*'Data Sheet'!I19,0) -> 110030 | ... M8: =IFERROR(SUM('Data Sheet'!L18,'Data Sheet'!L20:L22)-1*'Data Sheet'!L19,0) -> 0
B9: COGS % Sales | C9: =IFERROR(C8/C5,0) -> 0.65137842 | D9: =IFERROR(D8/D5,0) -> 0.65787981 | E9: =IFERROR(E8/E5,0) -> 0.67065014 | F9: =IFERROR(F8/F5,0) -> 0.68520007 | G9: =IFERROR(G8/G5,0) -> 0.68168246 | H9: =IFERROR(H8/H5,0) -> 0.69728957 | I9: =IFERROR(I8/I5,0) -> 0.71460206 | J9: =IFERROR(J8/J5,0) -> 0.71601484 | ... M9: =IFERROR(M8/M5,0) -> 0
B11: Gross Profit | C11: =IFERROR(C5-C8,0) -> 23875 | D11: =IFERROR(D5-D8,0) -> 24127 | E11: =IFERROR(E5-E8,0) -> 27229 | F11: =IFERROR(F5-F8,0) -> 28581 | G11: =IFERROR(G5-G8,0) -> 31982 | H11: =IFERROR(H5-H8,0) -> 36822 | I11: =IFERROR(I5-I8,0) -> 41887 | J11: =IFERROR(J5-J8,0) -> 43640 | ... M11: =IFERROR(M5-M8,0) -> 178650
B12: Gross Margin | C12: =IFERROR(C11/C5,0) -> 0.34862158 | D12: =IFERROR(D11/D5,0) -> 0.34212019 | E12: =IFERROR(E11/E5,0) -> 0.32934986 | F12: =IFERROR(F11/F5,0) -> 0.31479993 | G12: =IFERROR(G11/G5,0) -> 0.31831754 | H12: =IFERROR(H11/H5,0) -> 0.30271043 | I12: =IFERROR(I11/I5,0) -> 0.28539794 | J12: =IFERROR(J11/J5,0) -> 0.28398516 | ... M12: =IFERROR(M11/M5,0) -> 1
B14: Selling & General Exp | C14: =IFERROR(SUM('Data Sheet'!B23,'Data Sheet'!B24),0) -> 5271 | D14: =IFERROR(SUM('Data Sheet'!C23,'Data Sheet'!C24),0) -> 5305 | E14: =IFERROR(SUM('Data Sheet'!D23,'Data Sheet'!D24),0) -> 7059 | F14: =IFERROR(SUM('Data Sheet'!E23,'Data Sheet'!E24),0) -> 6314 | G14: =IFERROR(SUM('Data Sheet'!F23,'Data Sheet'!F24),0) -> 4093 | H14: =IFERROR(SUM('Data Sheet'!G23,'Data Sheet'!G24),0) -> 5331 | I14: =IFERROR(SUM('Data Sheet'!H23,'Data Sheet'!H24),0) -> 6757 | J14: =IFERROR(SUM('Data Sheet'!I23,'Data Sheet'!I24),0) -> 7215 | ... L14: =IFERROR(SUM('Data Sheet'!K23,'Data Sheet'!K24),0) -> 8113 | M14: =IFERROR(SUM('Data Sheet'!L23+'Data Sheet'!L24),0) -> 0
B15: S&G Exp % | C15: =IFERROR(C14/C5,0) -> 0.076966883 | D15: =IFERROR(D14/D5,0) -> 0.075224753 | E15: =IFERROR(E14/E5,0) -> 0.085382522 | F15: =IFERROR(F14/F5,0) -> 0.069544338 | G15: =IFERROR(G14/G5,0) -> 0.040737718 | H15: =IFERROR(H14/H5,0) -> 0.043825684 | I15: =IFERROR(I14/I5,0) -> 0.04603896 | J15: =IFERROR(J14/J5,0) -> 0.046951259 | ... M15: =IFERROR(M14/M5,0) -> 0
B17: EBITDA | C17: =IFERROR(C11-C14,0) -> 18604 | D17: =IFERROR(D11-D14,0) -> 18822 | E17: =IFERROR(E11-E14,0) -> 20170 | F17: =IFERROR(F11-F14,0) -> 22267 | G17: =IFERROR(G11-G14,0) -> 27889 | H17: =IFERROR(H11-H14,0) -> 31491 | I17: =IFERROR(I11-I14,0) -> 35130 | J17: =IFERROR(J11-J14,0) -> 36425 | ... M17: =IFERROR(M11-M14,0) -> 178650
B18: EBITDA Margin | C18: =IFERROR(C17/C5,0) -> 0.27165469 | D18: =IFERROR(D17/D5,0) -> 0.26689544 | E18: =IFERROR(E17/E5,0) -> 0.24396734 | F18: =IFERROR(F17/F5,0) -> 0.24525559 | G18: =IFERROR(G17/G5,0) -> 0.27757982 | H18: =IFERROR(H17/H5,0) -> 0.25888475 | I18: =IFERROR(I17/I5,0) -> 0.23935898 | J18: =IFERROR(J17/J5,0) -> 0.2370339 | ... M18: =IFERROR(M17/M5,0) -> 1
B20: Interest | C20: =IFERROR('Data Sheet'!B27,0) -> 0 | D20: =IFERROR('Data Sheet'!C27,0) -> 0 | E20: =IFERROR('Data Sheet'!D27,0) -> 0 | F20: =IFERROR('Data Sheet'!E27,0) -> 170 | G20: =IFERROR('Data Sheet'!F27,0) -> 195 | H20: =IFERROR('Data Sheet'!G27,0) -> 200 | I20: =IFERROR('Data Sheet'!H27,0) -> 284 | J20: =IFERROR('Data Sheet'!I27,0) -> 470 | ... L20: =IFERROR('Data Sheet'!K27,0) -> 416 | M20: =IFERROR(SUM('Data Sheet'!H46:K46),0) -> 416
B21: Interest % Sales | C21: =IFERROR(C20/C5,0) -> 0 | D21: =IFERROR(D20/D5,0) -> 0 | E21: =IFERROR(E20/E5,0) -> 0 | F21: =IFERROR(F20/F5,0) -> 0.0018724323 | G21: =IFERROR(G20/G5,0) -> 0.0019408392 | H21: =IFERROR(H20/H5,0) -> 0.0016441825 | I21: =IFERROR(I20/I5,0) -> 0.0019350399 | J21: =IFERROR(J20/J5,0) -> 0.003058502 | ... M21: =IFERROR(M20/M5,0) -> 0.0023285754
B23: Depreciation | C23: =IFERROR('Data Sheet'!B26,0) -> 1703 | D23: =IFERROR('Data Sheet'!C26,0) -> 1863 | E23: =IFERROR('Data Sheet'!D26,0) -> 2011 | F23: =IFERROR('Data Sheet'!E26,0) -> 2893 | G23: =IFERROR('Data Sheet'!F26,0) -> 3267 | H23: =IFERROR('Data Sheet'!G26,0) -> 3476 | I23: =IFERROR('Data Sheet'!H26,0) -> 4225 | J23: =IFERROR('Data Sheet'!I26,0) -> 4678 | ... L23: =IFERROR('Data Sheet'!K26,0) -> 4902 | M23: =IFERROR(SUM('Data Sheet'!H45:K45),0) -> 4901
B24: Depreciation % Sales | C24: =IFERROR(C23/C5,0) -> 0.024867122 | D24: =IFERROR(D23/D5,0) -> 0.026417288 | E24: =IFERROR(E23/E5,0) -> 0.024324161 | F24: =IFERROR(F23/F5,0) -> 0.031864392 | G24: =IFERROR(G23/G5,0) -> 0.032516522 | H24: =IFERROR(H23/H5,0) -> 0.028575891 | I24: =IFERROR(I23/I5,0) -> 0.028787125 | J24: =IFERROR(J23/J5,0) -> 0.030441856 | ... M24: =IFERROR(M23/M5,0) -> 0.027433529
B26: EBT | C26: =IFERROR(C17+'Data Sheet'!B25-SUM(C20,C23),0) -> 19951 | D26: =IFERROR(D17+'Data Sheet'!C25-SUM(D20,D23),0) -> 20270 | E26: =IFERROR(E17+'Data Sheet'!D25-SUM(E20,E23),0) -> 21041 | F26: =IFERROR(F17+'Data Sheet'!E25-SUM(F20,F23),0) -> 22007 | G26: =IFERROR(G17+'Data Sheet'!F25-SUM(G20,G23),0) -> 26628 | H26: =IFERROR(H17+'Data Sheet'!G25-SUM(H20,H23),0) -> 30110 | I26: =IFERROR(I17+'Data Sheet'!H25-SUM(I20,I23),0) -> 33322 | J26: =IFERROR(J17+'Data Sheet'!I25-SUM(J20,J23),0) -> 35988 | ... M26: =IFERROR(M17+'Data Sheet'!L25-SUM(M20,M23),0) -> 173333
B27: EBT Margin | C27: =IFERROR(C26/C5,0) -> 0.29132352 | D27: =IFERROR(D26/D5,0) -> 0.28742804 | E27: =IFERROR(E26/E5,0) -> 0.25450257 | F27: =IFERROR(F26/F5,0) -> 0.24239187 | G27: =IFERROR(G26/G5,0) -> 0.26502906 | H27: =IFERROR(H26/H5,0) -> 0.24753167 | I27: =IFERROR(I26/I5,0) -> 0.22704014 | J27: =IFERROR(J26/J5,0) -> 0.23419015 | ... M27: =IFERROR(M26/M5,0) -> 0.9702379
B29: Tax | C29: =IFERROR('Data Sheet'!B29,0) -> 5598 | D29: =IFERROR('Data Sheet'!C29,0) -> 4241 | E29: =IFERROR('Data Sheet'!D29,0) -> 5631 | F29: =IFERROR('Data Sheet'!E29,0) -> 5368 | G29: =IFERROR('Data Sheet'!F29,0) -> 7205 | H29: =IFERROR('Data Sheet'!G29,0) -> 7964 | I29: =IFERROR('Data Sheet'!H29,0) -> 9214 | J29: =IFERROR('Data Sheet'!I29,0) -> 9740 | ... M29: =IFERROR('Data Sheet'!L29,0) -> 0
B30: Effective Tax Rate | C30: =IFERROR(IF(C26>0,C29/C26,0),0) -> 0.28058744 | D30: =IFERROR(IF(D26>0,D29/D26,0),0) -> 0.20922546 | E30: =IFERROR(IF(E26>0,E29/E26,0),0) -> 0.26762036 | F30: =IFERROR(IF(F26>0,F29/F26,0),0) -> 0.24392239 | G30: =IFERROR(IF(G26>0,G29/G26,0),0) -> 0.27057984 | H30: =IFERROR(IF(H26>0,H29/H26,0),0) -> 0.26449684 | I30: =IFERROR(IF(I26>0,I29/I26,0),0) -> 0.27651401 | J30: =IFERROR(IF(J26>0,J29/J26,0),0) -> 0.27064577 | ... M30: =IFERROR(IF(M26>0,M29/M26,0),0) -> 0
B32: Net Profit | C32: =IFERROR(C26-C29,0) -> 14353 | D32: =IFERROR(D26-D29,0) -> 16029 | E32: =IFERROR(E26-E29,0) -> 15410 | F32: =IFERROR(F26-F29,0) -> 16639 | G32: =IFERROR(G26-G29,0) -> 19423 | H32: =IFERROR(H26-H29,0) -> 22146 | I32: =IFERROR(I26-I29,0) -> 24108 | J32: =IFERROR(J26-J29,0) -> 26248 | ... M32: =IFERROR(M26-M29,0) -> 173333
B33: Net Margin | C33: =IFERROR(C32/C5,0) -> 0.2095818 | D33: =IFERROR(D32/D5,0) -> 0.22729077 | E33: =IFERROR(E32/E5,0) -> 0.1863925 | F33: =IFERROR(F32/F5,0) -> 0.18326706 | G33: =IFERROR(G32/G5,0) -> 0.19331754 | H33: =IFERROR(H32/H5,0) -> 0.18206033 | I33: =IFERROR(I32/I5,0) -> 0.16426036 | J33: =IFERROR(J32/J5,0) -> 0.17080757 | ... M33: =IFERROR(M32/M5,0) -> 0.9702379
B35: No. of Equity Shares | C35: ='Data Sheet'!B93 -> 459.39 | D35: ='Data Sheet'!C93 -> 436.82 | E35: ='Data Sheet'!D93 -> 436.89 | F35: ='Data Sheet'!E93 -> 425.9 | G35: ='Data Sheet'!F93 -> 426.07 | H35: ='Data Sheet'!G93 -> 420.67 | I35: ='Data Sheet'!H93 -> 414.86 | J35: ='Data Sheet'!I93 -> 415.09 | ... M35: ='Data Sheet'!L93 -> 0
B37: EPS | C37: =IFERROR(C32/C35,0) -> 31.243606 | D37: =IFERROR(D32/D35,0) -> 36.694748 | E37: =IFERROR(E32/E35,0) -> 35.272036 | F37: =IFERROR(F32/F35,0) -> 39.067856 | G37: =IFERROR(G32/G35,0) -> 45.586406 | H37: =IFERROR(H32/H35,0) -> 52.644591 | I37: =IFERROR(I32/I35,0) -> 58.11117 | J37: =IFERROR(J32/J35,0) -> 63.234479 | ... M37: =IFERROR(M32/M35,0) -> 0
B38: EPS Growth | D38: =IFERROR(D37/C37-1,0) -> 0.17447227 | E38: =IFERROR(E37/D37-1,0) -> -0.038771542 | F38: =IFERROR(F37/E37-1,0) -> 0.10761556 | G38: =IFERROR(G37/F37-1,0) -> 0.16685199 | H38: =IFERROR(H37/G37-1,0) -> 0.15483091 | I38: =IFERROR(I37/H37-1,0) -> 0.10383933 | J38: =IFERROR(J37/I37-1,0) -> 0.088163932 | K38: =IFERROR(K37/J37-1,0) -> 0.018536361 | ... M38: =IFERROR(M37/L37-1,0) -> -1
B40: DPS | C40: =IFERROR('Data Sheet'!B31/HistoricalFS!C35,0) -> 12.824833 | D40: =IFERROR('Data Sheet'!C31/HistoricalFS!D35,0) -> 21.669337 | E40: =IFERROR('Data Sheet'!D31/HistoricalFS!E35,0) -> 21.109433 | F40: =IFERROR('Data Sheet'!E31/HistoricalFS!F35,0) -> 17.438366 | G40: =IFERROR('Data Sheet'!F31/HistoricalFS!G35,0) -> 26.91952 | H40: =IFERROR('Data Sheet'!G31/HistoricalFS!H35,0) -> 30.92115 | I40: =IFERROR('Data Sheet'!H31/HistoricalFS!I35,0) -> 33.913127 | J40: =IFERROR('Data Sheet'!I31/HistoricalFS!J35,0) -> 45.901371 | ... M40: =IFERROR('Data Sheet'!L31/HistoricalFS!M35,0) -> 0
B41: Dividend Payout Ratio | C41: =IFERROR(C40/C37,0) -> 0.41047865 | D41: =IFERROR(D40/D37,0) -> 0.59052966 | E41: =IFERROR(E40/E37,0) -> 0.59847502 | F41: =IFERROR(F40/F37,0) -> 0.44636096 | G41: =IFERROR(G40/G37,0) -> 0.5905164 | H41: =IFERROR(H40/H37,0) -> 0.58735663 | I41: =IFERROR(I40/I37,0) -> 0.58359051 | J41: =IFERROR(J40/J37,0) -> 0.7258915 | ... M41: =IFERROR(M40/M37,0) -> 0
B43: Retained Earnings | C43: =IFERROR(IF(C37>C40,1-C41,0),0) -> 0.58952135 | D43: =IFERROR(IF(D37>D40,1-D41,0),0) -> 0.40947034 | E43: =IFERROR(IF(E37>E40,1-E41,0),0) -> 0.40152498 | F43: =IFERROR(IF(F37>F40,1-F41,0),0) -> 0.55363904 | G43: =IFERROR(IF(G37>G40,1-G41,0),0) -> 0.4094836 | H43: =IFERROR(IF(H37>H40,1-H41,0),0) -> 0.41264337 | I43: =IFERROR(IF(I37>I40,1-I41,0),0) -> 0.41640949 | J43: =IFERROR(IF(J37>J40,1-J41,0),0) -> 0.2741085 | ... M43: =IFERROR(IF(M37>M40,1-M41,0),0) -> 0
A46: # | B46: Balance Sheet
B48: Equity Share Capital | C48: =IFERROR('Data Sheet'!B57,0) -> 1144 | D48: =IFERROR('Data Sheet'!C57,0) -> 1088 | E48: =IFERROR('Data Sheet'!D57,0) -> 2170 | F48: =IFERROR('Data Sheet'!E57,0) -> 2122 | G48: =IFERROR('Data Sheet'!F57,0) -> 2124 | H48: =IFERROR('Data Sheet'!G57,0) -> 2098 | I48: =IFERROR('Data Sheet'!H57,0) -> 2069 | J48: =IFERROR('Data Sheet'!I57,0) -> 2071 | ... L48: =IFERROR('Data Sheet'!K57,0) -> 2024
B49: Reserves | C49: =IFERROR('Data Sheet'!B58,0) -> 67838 | D49: =IFERROR('Data Sheet'!C58,0) -> 63835 | E49: =IFERROR('Data Sheet'!D58,0) -> 62778 | F49: =IFERROR('Data Sheet'!E58,0) -> 63328 | G49: =IFERROR('Data Sheet'!F58,0) -> 74227 | H49: =IFERROR('Data Sheet'!G58,0) -> 73252 | I49: =IFERROR('Data Sheet'!H58,0) -> 73338 | J49: =IFERROR('Data Sheet'!I58,0) -> 86045 | ... L49: =IFERROR('Data Sheet'!K58,0) -> 90828
B50: Borrowings | C50: =IFERROR('Data Sheet'!B59,0) -> 0 | D50: =IFERROR('Data Sheet'!C59,0) -> 0 | E50: =IFERROR('Data Sheet'!D59,0) -> 0 | F50: =IFERROR('Data Sheet'!E59,0) -> 4633 | G50: =IFERROR('Data Sheet'!F59,0) -> 5325 | H50: =IFERROR('Data Sheet'!G59,0) -> 5474 | I50: =IFERROR('Data Sheet'!H59,0) -> 8299 | J50: =IFERROR('Data Sheet'!I59,0) -> 8359 | ... L50: =IFERROR('Data Sheet'!K59,0) -> 9176
B51: Other Liabilities | C51: =IFERROR('Data Sheet'!B60,0) -> 14166 | D51: =IFERROR('Data Sheet'!C60,0) -> 14426 | E51: =IFERROR('Data Sheet'!D60,0) -> 19118 | F51: =IFERROR('Data Sheet'!E60,0) -> 21717 | G51: =IFERROR('Data Sheet'!F60,0) -> 25835 | H51: =IFERROR('Data Sheet'!G60,0) -> 35905 | I51: =IFERROR('Data Sheet'!H60,0) -> 40890 | J51: =IFERROR('Data Sheet'!I60,0) -> 39545 | ... L51: =IFERROR('Data Sheet'!K60,0) -> 52260
B52: Total Liabilities | C52: =IFERROR(SUM(C48:C51),0) -> 83148 | D52: =IFERROR(SUM(D48:D51),0) -> 79349 | E52: =IFERROR(SUM(E48:E51),0) -> 84066 | F52: =IFERROR(SUM(F48:F51),0) -> 91800 | G52: =IFERROR(SUM(G48:G51),0) -> 107511 | H52: =IFERROR(SUM(H48:H51),0) -> 116729 | I52: =IFERROR(SUM(I48:I51),0) -> 124596 | J52: =IFERROR(SUM(J48:J51),0) -> 136020 | ... L52: =IFERROR(SUM(L48:L51),0) -> 154288
B54: Fixed Aseet Net Block | C54: =IFERROR('Data Sheet'!B62,0) -> 14179 | D54: =IFERROR('Data Sheet'!C62,0) -> 12574 | E54: =IFERROR('Data Sheet'!D62,0) -> 15710 | F54: =IFERROR('Data Sheet'!E62,0) -> 23789 | G54: =IFERROR('Data Sheet'!F62,0) -> 25505 | H54: =IFERROR('Data Sheet'!G62,0) -> 25800 | I54: =IFERROR('Data Sheet'!H62,0) -> 29225 | J54: =IFERROR('Data Sheet'!I62,0) -> 27622 | ... L54: =IFERROR('Data Sheet'!K62,0) -> 33770
B55: Capital Work in Progress | C55: =IFERROR('Data Sheet'!B63,0) -> 1365 | D55: =IFERROR('Data Sheet'!C63,0) -> 1606 | E55: =IFERROR('Data Sheet'!D63,0) -> 1388 | F55: =IFERROR('Data Sheet'!E63,0) -> 954 | G55: =IFERROR('Data Sheet'!F63,0) -> 922 | H55: =IFERROR('Data Sheet'!G63,0) -> 416 | I55: =IFERROR('Data Sheet'!H63,0) -> 288 | J55: =IFERROR('Data Sheet'!I63,0) -> 293 | ... L55: =IFERROR('Data Sheet'!K63,0) -> 526
B56: Investments | C56: =IFERROR('Data Sheet'!B64,0) -> 16423 | D56: =IFERROR('Data Sheet'!C64,0) -> 12163 | E56: =IFERROR('Data Sheet'!D64,0) -> 11261 | F56: =IFERROR('Data Sheet'!E64,0) -> 8792 | G56: =IFERROR('Data Sheet'!F64,0) -> 14205 | H56: =IFERROR('Data Sheet'!G64,0) -> 20324 | I56: =IFERROR('Data Sheet'!H64,0) -> 19478 | J56: =IFERROR('Data Sheet'!I64,0) -> 24623 | ... L56: =IFERROR('Data Sheet'!K64,0) -> 21880
B57: Other Assets | C57: =IFERROR('Data Sheet'!B65-SUM('Data Sheet'!B67:B69),0) -> 16234 | D57: =IFERROR('Data Sheet'!C65-SUM('Data Sheet'!C67:C69),0) -> 20046 | E57: =IFERROR('Data Sheet'!D65-SUM('Data Sheet'!D67:D69),0) -> 21312 | F57: =IFERROR('Data Sheet'!E65-SUM('Data Sheet'!E67:E69),0) -> 21129 | G57: =IFERROR('Data Sheet'!F65-SUM('Data Sheet'!F67:F69),0) -> 22871 | H57: =IFERROR('Data Sheet'!G65-SUM('Data Sheet'!G67:G69),0) -> 30019 | I57: =IFERROR('Data Sheet'!H65-SUM('Data Sheet'!H67:H69),0) -> 38008 | J57: =IFERROR('Data Sheet'!I65-SUM('Data Sheet'!I67:I69),0) -> 38503 | ... L57: =IFERROR('Data Sheet'!K65-SUM('Data Sheet'!K67:K69),0) -> 40677
B58: Total Non Current Asset | C58: =IFERROR(SUM(C54:C57),0) -> 48201 | D58: =IFERROR(SUM(D54:D57),0) -> 46389 | E58: =IFERROR(SUM(E54:E57),0) -> 49671 | F58: =IFERROR(SUM(F54:F57),0) -> 54664 | G58: =IFERROR(SUM(G54:G57),0) -> 63503 | H58: =IFERROR(SUM(H54:H57),0) -> 76559 | I58: =IFERROR(SUM(I54:I57),0) -> 86999 | J58: =IFERROR(SUM(J54:J57),0) -> 91041 | ... L58: =IFERROR(SUM(L54:L57),0) -> 96853
...

Sheet Ratio Analysis
B2: ="Ratio Analysis-"&'Data Sheet'!B1 -> Ratio Analysis-INFOSYS LTD
B3: Years | C3: ='Data Sheet'!B16 -> 42825 | D3: ='Data Sheet'!C16 -> 43190 | E3: ='Data Sheet'!D16 -> 43555 | F3: ='Data Sheet'!E16 -> 43921 | G3: ='Data Sheet'!F16 -> 44286 | H3: ='Data Sheet'!G16 -> 44651 | I3: ='Data Sheet'!H16 -> 45016 | J3: ='Data Sheet'!I16 -> 45382 | ... L3: ='Data Sheet'!K16 -> 46112 | N3: Mean | O3: Median
B5: Sales Growth | D5: =IFERROR(HistoricalFS!D6,0) -> 0.029758776 | E5: =IFERROR(HistoricalFS!E6,0) -> 0.1723292 | F5: =IFERROR(HistoricalFS!F6,0) -> 0.098167523 | G5: =IFERROR(HistoricalFS!G6,0) -> 0.10662951 | H5: =IFERROR(HistoricalFS!H6,0) -> 0.21069552 | I5: =IFERROR(HistoricalFS!I6,0) -> 0.20655864 | J5: =IFERROR(HistoricalFS!J6,0) -> 0.047033734 | K5: =IFERROR(HistoricalFS!K6,0) -> 0.060649444 | L5: =IFERROR(HistoricalFS!L6,0) -> 0.096079514 | N5: =AVERAGE(D5:L5) -> 0.11421132 | O5: =MEDIAN(D5:L5) -> 0.098167523
B6: EBITDA Growth | D6: =IFERROR(HistoricalFS!D17/HistoricalFS!C17-1,0) -> 0.01171791 | E6: =IFERROR(HistoricalFS!E17/HistoricalFS!D17-1,0) -> 0.071618319 | F6: =IFERROR(HistoricalFS!F17/HistoricalFS!E17-1,0) -> 0.10396629 | G6: =IFERROR(HistoricalFS!G17/HistoricalFS!F17-1,0) -> 0.25248125 | H6: =IFERROR(HistoricalFS!H17/HistoricalFS!G17-1,0) -> 0.12915486 | I6: =IFERROR(HistoricalFS!I17/HistoricalFS!H17-1,0) -> 0.11555683 | J6: =IFERROR(HistoricalFS!J17/HistoricalFS!I17-1,0) -> 0.03686308 | K6: =IFERROR(HistoricalFS!K17/HistoricalFS!J17-1,0) -> 0.077172272 | L6: =IFERROR(HistoricalFS!L17/HistoricalFS!K17-1,0) -> 0.077581813 | N6: =AVERAGE(D6:L6) -> 0.097345847 | O6: =MEDIAN(D6:L6) -> 0.077581813
B7: EBT Growth | D7: =IFERROR(HistoricalFS!D26/HistoricalFS!C26-1,0) -> 0.015989173 | E7: =IFERROR(HistoricalFS!E26/HistoricalFS!D26-1,0) -> 0.038036507 | F7: =IFERROR(HistoricalFS!F26/HistoricalFS!E26-1,0) -> 0.045910365 | G7: =IFERROR(HistoricalFS!G26/HistoricalFS!F26-1,0) -> 0.20997864 | H7: =IFERROR(HistoricalFS!H26/HistoricalFS!G26-1,0) -> 0.13076461 | I7: =IFERROR(HistoricalFS!I26/HistoricalFS!H26-1,0) -> 0.10667552 | J7: =IFERROR(HistoricalFS!J26/HistoricalFS!I26-1,0) -> 0.080007202 | K7: =IFERROR(HistoricalFS!K26/HistoricalFS!J26-1,0) -> 0.045015005 | L7: =IFERROR(HistoricalFS!L26/HistoricalFS!K26-1,0) -> 0.063470538 | N7: =AVERAGE(D7:L7) -> 0.081760841 | O7: =MEDIAN(D7:L7) -> 0.063470538
B8: Net Profit Growth | D8: =IFERROR(HistoricalFS!D32/HistoricalFS!C32-1,0) -> 0.11677001 | E8: =IFERROR(HistoricalFS!E32/HistoricalFS!D32-1,0) -> -0.038617506 | F8: =IFERROR(HistoricalFS!F32/HistoricalFS!E32-1,0) -> 0.079753407 | G8: =IFERROR(HistoricalFS!G32/HistoricalFS!F32-1,0) -> 0.16731775 | H8: =IFERROR(HistoricalFS!H32/HistoricalFS!G32-1,0) -> 0.14019461 | I8: =IFERROR(HistoricalFS!I32/HistoricalFS!H32-1,0) -> 0.088593877 | J8: =IFERROR(HistoricalFS!J32/HistoricalFS!I32-1,0) -> 0.088767214 | K8: =IFERROR(HistoricalFS!K32/HistoricalFS!J32-1,0) -> 0.019125267 | L8: =IFERROR(HistoricalFS!L32/HistoricalFS!K32-1,0) -> 0.10183178 | N8: =AVERAGE(D8:L8) -> 0.084859601 | O8: =MEDIAN(D8:L8) -> 0.088767214
B9: Dividend Growth | D9: =IFERROR(HistoricalFS!D40/HistoricalFS!C40-1,0) -> 0.68963897 | E9: =IFERROR(HistoricalFS!E40/HistoricalFS!D40-1,0) -> -0.02583858 | F9: =IFERROR(HistoricalFS!F40/HistoricalFS!E40-1,0) -> -0.17390646 | G9: =IFERROR(HistoricalFS!G40/HistoricalFS!F40-1,0) -> 0.54369512 | H9: =IFERROR(HistoricalFS!H40/HistoricalFS!G40-1,0) -> 0.14865158 | I9: =IFERROR(HistoricalFS!I40/HistoricalFS!H40-1,0) -> 0.096761529 | J9: =IFERROR(HistoricalFS!J40/HistoricalFS!I40-1,0) -> 0.35349861 | K9: =IFERROR(HistoricalFS!K40/HistoricalFS!J40-1,0) -> -0.064855345 | L9: =IFERROR(HistoricalFS!L40/HistoricalFS!K40-1,0) -> 0.116149 | N9: =AVERAGE(D9:L9) -> 0.18708827 | O9: =MEDIAN(D9:L9) -> 0.116149
B11: Gross Margin | C11: =IFERROR(HistoricalFS!C12,0) -> 0.34862158 | D11: =IFERROR(HistoricalFS!D12,0) -> 0.34212019 | E11: =IFERROR(HistoricalFS!E12,0) -> 0.32934986 | F11: =IFERROR(HistoricalFS!F12,0) -> 0.31479993 | G11: =IFERROR(HistoricalFS!G12,0) -> 0.31831754 | H11: =IFERROR(HistoricalFS!H12,0) -> 0.30271043 | I11: =IFERROR(HistoricalFS!I12,0) -> 0.28539794 | J11: =IFERROR(HistoricalFS!J12,0) -> 0.28398516 | ... L11: =IFERROR(HistoricalFS!L12,0) -> 0.28207669 | N11: =AVERAGE(D11:L11) -> 0.30482983 | O11: =MEDIAN(D11:L11) -> 0.30271043
B12: EBITDA Margin | C12: =IFERROR(HistoricalFS!C18,0) -> 0.27165469 | D12: =IFERROR(HistoricalFS!D18,0) -> 0.26689544 | E12: =IFERROR(HistoricalFS!E18,0) -> 0.24396734 | F12: =IFERROR(HistoricalFS!F18,0) -> 0.24525559 | G12: =IFERROR(HistoricalFS!G18,0) -> 0.27757982 | H12: =IFERROR(HistoricalFS!H18,0) -> 0.25888475 | I12: =IFERROR(HistoricalFS!I18,0) -> 0.23935898 | J12: =IFERROR(HistoricalFS!J18,0) -> 0.2370339 | ... L12: =IFERROR(HistoricalFS!L18,0) -> 0.23666387 | N12: =AVERAGE(D12:L12) -> 0.24959624 | O12: =MEDIAN(D12:L12) -> 0.24396734
B13: EBIT Margin | C13: =IFERROR((HistoricalFS!C17-HistoricalFS!C23)/HistoricalFS!C5,0) -> 0.24678757 | D13: =IFERROR((HistoricalFS!D17-HistoricalFS!D23)/HistoricalFS!D5,0) -> 0.24047815 | E13: =IFERROR((HistoricalFS!E17-HistoricalFS!E23)/HistoricalFS!E5,0) -> 0.21964318 | F13: =IFERROR((HistoricalFS!F17-HistoricalFS!F23)/HistoricalFS!F5,0) -> 0.2133912 | G13: =IFERROR((HistoricalFS!G17-HistoricalFS!G23)/HistoricalFS!G5,0) -> 0.2450633 | H13: =IFERROR((HistoricalFS!H17-HistoricalFS!H23)/HistoricalFS!H5,0) -> 0.23030886 | I13: =IFERROR((HistoricalFS!I17-HistoricalFS!I23)/HistoricalFS!I5,0) -> 0.21057186 | J13: =IFERROR((HistoricalFS!J17-HistoricalFS!J23)/HistoricalFS!J5,0) -> 0.20659205 | ... L13: =IFERROR((HistoricalFS!L17-HistoricalFS!L23)/HistoricalFS!L5,0) -> 0.20922474 | N13: =AVERAGE(D13:L13) -> 0.22071961 | O13: =MEDIAN(D13:L13) -> 0.2133912
B14: EBT Margin | C14: =IFERROR(HistoricalFS!C27,0) -> 0.29132352 | D14: =IFERROR(HistoricalFS!D27,0) -> 0.28742804 | E14: =IFERROR(HistoricalFS!E27,0) -> 0.25450257 | F14: =IFERROR(HistoricalFS!F27,0) -> 0.24239187 | G14: =IFERROR(HistoricalFS!G27,0) -> 0.26502906 | H14: =IFERROR(HistoricalFS!H27,0) -> 0.24753167 | I14: =IFERROR(HistoricalFS!I27,0) -> 0.22704014 | J14: =IFERROR(HistoricalFS!J27,0) -> 0.23419015 | ... L14: =IFERROR(HistoricalFS!L27,0) -> 0.2238735 | N14: =AVERAGE(D14:L14) -> 0.24585834 | O14: =MEDIAN(D14:L14) -> 0.24239187
B15: Net Profit Margin | C15: =IFERROR(HistoricalFS!C33,0) -> 0.2095818 | D15: =IFERROR(HistoricalFS!D33,0) -> 0.22729077 | E15: =IFERROR(HistoricalFS!E33,0) -> 0.1863925 | F15: =IFERROR(HistoricalFS!F33,0) -> 0.18326706 | G15: =IFERROR(HistoricalFS!G33,0) -> 0.19331754 | H15: =IFERROR(HistoricalFS!H33,0) -> 0.18206033 | I15: =IFERROR(HistoricalFS!I33,0) -> 0.16426036 | J15: =IFERROR(HistoricalFS!J33,0) -> 0.17080757 | ... L15: =IFERROR(HistoricalFS!L33,0) -> 0.16498181 | N15: =AVERAGE(D15:L15) -> 0.18183316 | O15: =MEDIAN(D15:L15) -> 0.18206033
B17: S&G Exp% | C17: =IFERROR(HistoricalFS!C15,0) -> 0.076966883 | D17: =IFERROR(HistoricalFS!D15,0) -> 0.075224753 | E17: =IFERROR(HistoricalFS!E15,0) -> 0.085382522 | F17: =IFERROR(HistoricalFS!F15,0) -> 0.069544338 | G17: =IFERROR(HistoricalFS!G15,0) -> 0.040737718 | H17: =IFERROR(HistoricalFS!H15,0) -> 0.043825684 | I17: =IFERROR(HistoricalFS!I15,0) -> 0.04603896 | J17: =IFERROR(HistoricalFS!J15,0) -> 0.046951259 | ... L17: =IFERROR(HistoricalFS!L15,0) -> 0.045412818 | N17: =AVERAGE(D17:L17) -> 0.055233594 | O17: =MEDIAN(D17:L17) -> 0.04603896
B18: Operating Income %Sales | C18: =IFERROR(C13,0) -> 0.24678757 | D18: =IFERROR(D13,0) -> 0.24047815 | E18: =IFERROR(E13,0) -> 0.21964318 | F18: =IFERROR(F13,0) -> 0.2133912 | G18: =IFERROR(G13,0) -> 0.2450633 | H18: =IFERROR(H13,0) -> 0.23030886 | I18: =IFERROR(I13,0) -> 0.21057186 | J18: =IFERROR(J13,0) -> 0.20659205 | ... L18: =IFERROR(L13,0) -> 0.20922474 | N18: =AVERAGE(D18:L18) -> 0.22071961 | O18: =MEDIAN(D18:L18) -> 0.2133912
B19: Depreciation% Sales | C19: =IFERROR(HistoricalFS!C24,0) -> 0.024867122 | D19: =IFERROR(HistoricalFS!D24,0) -> 0.026417288 | E19: =IFERROR(HistoricalFS!E24,0) -> 0.024324161 | F19: =IFERROR(HistoricalFS!F24,0) -> 0.031864392 | G19: =IFERROR(HistoricalFS!G24,0) -> 0.032516522 | H19: =IFERROR(HistoricalFS!H24,0) -> 0.028575891 | I19: =IFERROR(HistoricalFS!I24,0) -> 0.028787125 | J19: =IFERROR(HistoricalFS!J24,0) -> 0.030441856 | ... L19: =IFERROR(HistoricalFS!L24,0) -> 0.027439127 | N19: =AVERAGE(D19:L19) -> 0.028876627 | O19: =MEDIAN(D19:L19) -> 0.028787125
B21: Return on Capital Employed | C21: =IFERROR((HistoricalFS!C17-HistoricalFS!C23)/SUM(HistoricalFS!C48:C50),0) -> 0.24500594 | D21: =IFERROR((HistoricalFS!D17-HistoricalFS!D23)/SUM(HistoricalFS!D48:D50),0) -> 0.26121713 | E21: =IFERROR((HistoricalFS!E17-HistoricalFS!E23)/SUM(HistoricalFS!E48:E50),0) -> 0.27959291 | F21: =IFERROR((HistoricalFS!F17-HistoricalFS!F23)/SUM(HistoricalFS!F48:F50),0) -> 0.27644365 | G21: =IFERROR((HistoricalFS!G17-HistoricalFS!G23)/SUM(HistoricalFS!G48:G50),0) -> 0.30145943 | H21: =IFERROR((HistoricalFS!H17-HistoricalFS!H23)/SUM(HistoricalFS!H48:H50),0) -> 0.34661734 | I21: =IFERROR((HistoricalFS!I17-HistoricalFS!I23)/SUM(HistoricalFS!I48:I50),0) -> 0.3692089 | J21: =IFERROR((HistoricalFS!J17-HistoricalFS!J23)/SUM(HistoricalFS!J48:J50),0) -> 0.32906971 | ... L21: =IFERROR((HistoricalFS!L17-HistoricalFS!L23)/SUM(HistoricalFS!L48:L50),0) -> 0.36635041 | N21: =AVERAGE(D21:L21) -> 0.31786848 | O21: =MEDIAN(D21:L21) -> 0.32906971
B22: Retained Earnings | C22: =IFERROR(HistoricalFS!C43,0) -> 0.58952135 | D22: =IFERROR(HistoricalFS!D43,0) -> 0.40947034 | E22: =IFERROR(HistoricalFS!E43,0) -> 0.40152498 | F22: =IFERROR(HistoricalFS!F43,0) -> 0.55363904 | G22: =IFERROR(HistoricalFS!G43,0) -> 0.4094836 | H22: =IFERROR(HistoricalFS!H43,0) -> 0.41264337 | I22: =IFERROR(HistoricalFS!I43,0) -> 0.41640949 | J22: =IFERROR(HistoricalFS!J43,0) -> 0.2741085 | ... L22: =IFERROR(HistoricalFS!L43,0) -> 0.34076135 | N22: =AVERAGE(D22:L22) -> 0.3946201 | O22: =MEDIAN(D22:L22) -> 0.40947034
B23: Return on Equity% | C23: =IFERROR(HistoricalFS!C32/SUM(HistoricalFS!C48:C49),0) -> 0.20806877 | D23: =IFERROR(HistoricalFS!D32/SUM(HistoricalFS!D48:D49),0) -> 0.24689247 | E23: =IFERROR(HistoricalFS!E32/SUM(HistoricalFS!E48:E49),0) -> 0.23726674 | F23: =IFERROR(HistoricalFS!F32/SUM(HistoricalFS!F48:F49),0) -> 0.2542246 | G23: =IFERROR(HistoricalFS!G32/SUM(HistoricalFS!G48:G49),0) -> 0.25439091 | H23: =IFERROR(HistoricalFS!H32/SUM(HistoricalFS!H48:H49),0) -> 0.29390843 | I23: =IFERROR(HistoricalFS!I32/SUM(HistoricalFS!I48:I49),0) -> 0.31970507 | J23: =IFERROR(HistoricalFS!J32/SUM(HistoricalFS!J48:J49),0) -> 0.29788007 | ... L23: =IFERROR(HistoricalFS!L32/SUM(HistoricalFS!L48:L49),0) -> 0.31742989 | N23: =AVERAGE(D23:L23) -> 0.27787481 | O23: =MEDIAN(D23:L23) -> 0.2791751
B24: Self Sustain Growth Rate | C24: =IFERROR(C22*C23,0) -> 0.12266098 | D24: =IFERROR(D22*D23,0) -> 0.10109514 | E24: =IFERROR(E22*E23,0) -> 0.095268523 | F24: =IFERROR(F22*F23,0) -> 0.14074866 | G24: =IFERROR(G22*G23,0) -> 0.1041689 | H24: =IFERROR(H22*H23,0) -> 0.12127936 | I24: =IFERROR(I22*I23,0) -> 0.13312822 | J24: =IFERROR(J22*J23,0) -> 0.081651459 | ... L24: =IFERROR(L22*L23,0) -> 0.10816784 | N24: =AVERAGE(D24:L24) -> 0.10873603 | O24: =MEDIAN(D24:L24) -> 0.1041689
B25: Interest Coverage Ratio | C25: =IFERROR((HistoricalFS!C17-HistoricalFS!C23)/HistoricalFS!C20,0) -> 0 | D25: =IFERROR((HistoricalFS!D17-HistoricalFS!D23)/HistoricalFS!D20,0) -> 0 | E25: =IFERROR((HistoricalFS!E17-HistoricalFS!E23)/HistoricalFS!E20,0) -> 0 | F25: =IFERROR((HistoricalFS!F17-HistoricalFS!F23)/HistoricalFS!F20,0) -> 113.96471 | G25: =IFERROR((HistoricalFS!G17-HistoricalFS!G23)/HistoricalFS!G20,0) -> 126.26667 | H25: =IFERROR((HistoricalFS!H17-HistoricalFS!H23)/HistoricalFS!H20,0) -> 140.075 | I25: =IFERROR((HistoricalFS!I17-HistoricalFS!I23)/HistoricalFS!I20,0) -> 108.82042 | J25: =IFERROR((HistoricalFS!J17-HistoricalFS!J23)/HistoricalFS!J20,0) -> 67.546809 | ... L25: =IFERROR((HistoricalFS!L17-HistoricalFS!L23)/HistoricalFS!L20,0) -> 89.850962 | N25: =AVERAGE(D25:L25) -> 81.030507 | O25: =MEDIAN(C25:L25) -> 86.300481
B27: Debtor Turnover Ratio | C27: =IFERROR(HistoricalFS!C5/HistoricalFS!C60,0) -> 5.557864 | D27: =IFERROR(HistoricalFS!D5/HistoricalFS!D60,0) -> 5.3661543 | E27: =IFERROR(HistoricalFS!E5/HistoricalFS!E60,0) -> 5.5759763 | F27: =IFERROR(HistoricalFS!F5/HistoricalFS!F60,0) -> 4.9110726 | G27: =IFERROR(HistoricalFS!G5/HistoricalFS!G60,0) -> 5.207422 | H27: =IFERROR(HistoricalFS!H5/HistoricalFS!H60,0) -> 5.3591065 | I27: =IFERROR(HistoricalFS!I5/HistoricalFS!I60,0) -> 5.7727738 | J27: =IFERROR(HistoricalFS!J5/HistoricalFS!J60,0) -> 5.0895903 | ... L27: =IFERROR(HistoricalFS!L5/HistoricalFS!L60,0) -> 5.0703866 | N27: =AVERAGE(D27:L27) -> 5.2870625 | O27: =MEDIAN(C27:L27) -> 5.2950934
B28: Creditor Turnover Ratio | C28: =IFERROR(HistoricalFS!C5/HistoricalFS!C51,0) -> 4.8343922 | D28: =IFERROR(HistoricalFS!D5/HistoricalFS!D51,0) -> 4.8885346 | E28: =IFERROR(HistoricalFS!E5/HistoricalFS!E51,0) -> 4.3244586 | F28: =IFERROR(HistoricalFS!F5/HistoricalFS!F51,0) -> 4.1806419 | G28: =IFERROR(HistoricalFS!G5/HistoricalFS!G51,0) -> 3.8889878 | H28: =IFERROR(HistoricalFS!H5/HistoricalFS!H51,0) -> 3.3878568 | I28: =IFERROR(HistoricalFS!I5/HistoricalFS!I51,0) -> 3.5893128 | J28: =IFERROR(HistoricalFS!J5/HistoricalFS!J51,0) -> 3.8859527 | ... L28: =IFERROR(HistoricalFS!L5/HistoricalFS!L51,0) -> 3.4184845 | N28: =AVERAGE(D28:L28) -> 3.9210795 | O28: =MEDIAN(C28:L28) -> 3.8874703
B29: Fixed Asset Turnover Ratio | C29: =IFERROR(HistoricalFS!C5/HistoricalFS!C54,0) -> 4.8299598 | D29: =IFERROR(HistoricalFS!D5/HistoricalFS!D54,0) -> 5.6085573 | E29: =IFERROR(HistoricalFS!E5/HistoricalFS!E54,0) -> 5.2625716 | F29: =IFERROR(HistoricalFS!F5/HistoricalFS!F54,0) -> 3.8165118 | G29: =IFERROR(HistoricalFS!G5/HistoricalFS!G54,0) -> 3.939306 | H29: =IFERROR(HistoricalFS!H5/HistoricalFS!H54,0) -> 4.7147674 | I29: =IFERROR(HistoricalFS!I5/HistoricalFS!I54,0) -> 5.0219675 | J29: =IFERROR(HistoricalFS!J5/HistoricalFS!J54,0) -> 5.5633191 | ... L29: =IFERROR(HistoricalFS!L5/HistoricalFS!L54,0) -> 5.2901984 | N29: =AVERAGE(D29:L29) -> 4.942396 | O29: =MEDIAN(C29:L29) -> 5.1422696
B30: Inventory Turnover Ratio | C30: =IFERROR(HistoricalFS!C5/HistoricalFS!C61,0) -> 0 | D30: =IFERROR(HistoricalFS!D5/HistoricalFS!D61,0) -> 0 | E30: =IFERROR(HistoricalFS!E5/HistoricalFS!E61,0) -> 0 | F30: =IFERROR(HistoricalFS!F5/HistoricalFS!F61,0) -> 0 | G30: =IFERROR(HistoricalFS!G5/HistoricalFS!G61,0) -> 0 | H30: =IFERROR(HistoricalFS!H5/HistoricalFS!H61,0) -> 0 | I30: =IFERROR(HistoricalFS!I5/HistoricalFS!I61,0) -> 0 | J30: =IFERROR(HistoricalFS!J5/HistoricalFS!J61,0) -> 0 | ... L30: =IFERROR(HistoricalFS!L5/HistoricalFS!L61,0) -> 0 | N30: =AVERAGE(D30:L30) -> 0 | O30: =MEDIAN(C30:L30) -> 0
B31: Capital Turnover Ratio | C31: =IFERROR(HistoricalFS!C5/SUM(HistoricalFS!C48:C49),0) -> 0.99278073 | D31: =IFERROR(HistoricalFS!D5/SUM(HistoricalFS!D48:D49),0) -> 1.0862406 | E31: =IFERROR(HistoricalFS!E5/SUM(HistoricalFS!E48:E49),0) -> 1.2729414 | F31: =IFERROR(HistoricalFS!F5/SUM(HistoricalFS!F48:F49),0) -> 1.3871811 | G31: =IFERROR(HistoricalFS!G5/SUM(HistoricalFS!G48:G49),0) -> 1.3159225 | H31: =IFERROR(HistoricalFS!H5/SUM(HistoricalFS!H48:H49),0) -> 1.6143464 | I31: =IFERROR(HistoricalFS!I5/SUM(HistoricalFS!I48:I49),0) -> 1.9463312 | J31: =IFERROR(HistoricalFS!J5/SUM(HistoricalFS!J48:J49),0) -> 1.7439512 | ... L31: =IFERROR(HistoricalFS!L5/SUM(HistoricalFS!L48:L49),0) -> 1.9240296 | N31: =AVERAGE(D31:L31) -> 1.5546646 | O31: =MEDIAN(C31:L31) -> 1.5007637
B33: (In days)
B34: Debtors Days | C34: =IFERROR(365/C27,0) -> 65.672712 | D34: =IFERROR(365/D27,0) -> 68.018916 | E34: =IFERROR(365/E27,0) -> 65.459389 | F34: =IFERROR(365/F27,0) -> 74.321849 | G34: =IFERROR(365/G27,0) -> 70.092265 | H34: =IFERROR(365/H27,0) -> 68.108368 | I34: =IFERROR(365/I27,0) -> 63.227837 | J34: =IFERROR(365/J27,0) -> 71.715006 | ... L34: =IFERROR(365/L27,0) -> 71.986622 | N34: =AVERAGE(D34:L34) -> 69.189502 | O34: =MEDIAN(C34:L34) -> 68.941815
B35: Payable Days | C35: =IFERROR(365/C28,0) -> 75.500701 | D35: =IFERROR(365/D28,0) -> 74.664502 | E35: =IFERROR(365/E28,0) -> 84.403629 | F35: =IFERROR(365/F28,0) -> 87.307167 | G35: =IFERROR(365/G28,0) -> 93.854756 | H35: =IFERROR(365/H28,0) -> 107.73773 | I35: =IFERROR(365/I28,0) -> 101.69078 | J35: =IFERROR(365/J28,0) -> 93.92806 | ... L35: =IFERROR(365/L28,0) -> 106.77246 | N35: =AVERAGE(D35:L35) -> 94.259209 | O35: =MEDIAN(C35:L35) -> 93.891408
B36: Inventory Days | C36: =IFERROR(365/C30,0) -> 0 | D36: =IFERROR(365/D30,0) -> 0 | E36: =IFERROR(365/E30,0) -> 0 | F36: =IFERROR(365/F30,0) -> 0 | G36: =IFERROR(365/G30,0) -> 0 | H36: =IFERROR(365/H30,0) -> 0 | I36: =IFERROR(365/I30,0) -> 0 | J36: =IFERROR(365/J30,0) -> 0 | ... L36: =IFERROR(365/L30,0) -> 0 | N36: =AVERAGE(D36:L36) -> 0 | O36: =MEDIAN(C36:L36) -> 0
B37: Cash Conversion Cycle | C37: =IFERROR(SUM(C34,C36)-C35,0) -> -9.827989 | D37: =IFERROR(SUM(D34,D36)-D35,0) -> -6.6455858 | E37: =IFERROR(SUM(E34,E36)-E35,0) -> -18.944239 | F37: =IFERROR(SUM(F34,F36)-F35,0) -> -12.985318 | G37: =IFERROR(SUM(G34,G36)-G35,0) -> -23.762491 | H37: =IFERROR(SUM(H34,H36)-H35,0) -> -39.62936 | I37: =IFERROR(SUM(I34,I36)-I35,0) -> -38.462938 | J37: =IFERROR(SUM(J34,J36)-J35,0) -> -22.213054 | ... L37: =IFERROR(SUM(L34,L36)-L35,0) -> -34.785838 | N37: =AVERAGE(C37:L37) -> -23.545535 | O37: =MEDIAN(C37:L37) -> -22.987772
B39: CFO/Sales | C39: =IFERROR(HistoricalFS!C80/HistoricalFS!C5,0) -> 0.16837509 | D39: =IFERROR(HistoricalFS!D80/HistoricalFS!D5,0) -> 0.18743087 | E39: =IFERROR(HistoricalFS!E80/HistoricalFS!E5,0) -> 0.17951013 | F39: =IFERROR(HistoricalFS!F80/HistoricalFS!F5,0) -> 0.18727627 | G39: =IFERROR(HistoricalFS!G80/HistoricalFS!G5,0) -> 0.23114898 | H39: =IFERROR(HistoricalFS!H80/HistoricalFS!H5,0) -> 0.19635649 | I39: =IFERROR(HistoricalFS!I80/HistoricalFS!I5,0) -> 0.15307937 | J39: =IFERROR(HistoricalFS!J80/HistoricalFS!J5,0) -> 0.16405284 | ... L39: =IFERROR(HistoricalFS!L80/HistoricalFS!L5,0) -> 0.1902379 | N39: =AVERAGE(D39:L39) -> 0.18978754 | O39: =MEDIAN(C39:L39) -> 0.18735357
B40: CFO/Total Asset | C40: =IFERROR(HistoricalFS!C80/HistoricalFS!C65,0) -> 0.13868043 | D40: =IFERROR(HistoricalFS!D80/HistoricalFS!D65,0) -> 0.16658055 | E40: =IFERROR(HistoricalFS!E80/HistoricalFS!E65,0) -> 0.17653986 | F40: =IFERROR(HistoricalFS!F80/HistoricalFS!F65,0) -> 0.18521786 | G40: =IFERROR(HistoricalFS!G80/HistoricalFS!G65,0) -> 0.21601511 | H40: =IFERROR(HistoricalFS!H80/HistoricalFS!H65,0) -> 0.20461925 | I40: =IFERROR(HistoricalFS!I80/HistoricalFS!I65,0) -> 0.18031879 | J40: =IFERROR(HistoricalFS!J80/HistoricalFS!J65,0) -> 0.18534039 | ... L40: =IFERROR(HistoricalFS!L80/HistoricalFS!L65,0) -> 0.22027637 | N40: =AVERAGE(D40:L40) -> 0.19737982 | O40: =MEDIAN(C40:L40) -> 0.18527913
B41: CFO/Total Debt | C41: =IFERROR(HistoricalFS!C80/HistoricalFS!C50,0) -> 0 | D41: =IFERROR(HistoricalFS!D80/HistoricalFS!D50,0) -> 0 | E41: =IFERROR(HistoricalFS!E80/HistoricalFS!E50,0) -> 0 | F41: =IFERROR(HistoricalFS!F80/HistoricalFS!F50,0) -> 3.6699763 | G41: =IFERROR(HistoricalFS!G80/HistoricalFS!G50,0) -> 4.3613146 | H41: =IFERROR(HistoricalFS!H80/HistoricalFS!H50,0) -> 4.363354 | I41: =IFERROR(HistoricalFS!I80/HistoricalFS!I50,0) -> 2.7071936 | J41: =IFERROR(HistoricalFS!J80/HistoricalFS!J50,0) -> 3.015911 | ... L41: =IFERROR(HistoricalFS!L80/HistoricalFS!L50,0) -> 3.7037925 | N41: =AVERAGE(D41:L41) -> 2.906687 | O41: =MEDIAN(C41:L41) -> 3.3429436

Sheet WACC
B5: Weighted Average Cost of Capital
B7: All figures are in the INR otherwise
B9: Peer Comps
G12: Debt/ | H12: Debt/ | I12: Levered | J12: Unlevered
B13: Name of the Comp | C13: Country | D13: Total Debt | E13: Total Equity | F13: Tax Rate 1 | G13: Equity | H13: Capital | I13: Beta 2 | J13: Beta 3
B15: TCS | C15: India | D15: =COMPS!F7 -> 11283 | E15: =COMPS!E7 -> 855894.78 | F15: 0.3 | G15: =D15/E15 -> 0.013182695 | H15: =D15/(D15+E15) -> 0.013011173 | I15: 0.911 | J15: =I15/(1+(1-F15)*G15) -> 0.90267026
B16: Infosys | C16: India | D16: =COMPS!F8 -> 8737 | E16: =COMPS!E8 -> 458546.98 | F16: 0.3 | G16: =D16/E16 -> 0.019053664 | H16: =D16/(D16+E16) -> 0.01869741 | I16: 0.78 | J16: =I16/(1+(1-F16)*G16) -> 0.76973363
B17: HCL Technologies | C17: India | D17: =COMPS!F9 -> 5215 | E17: =COMPS!E9 -> 365503.55 | F17: 0.3 | G17: =D17/E17 -> 0.014267987 | H17: =D17/(D17+E17) -> 0.014067276 | I17: 1.02 | J17: =I17/(1+(1-F17)*G17) -> 1.0099134
B18: Wipro | C18: India | D18: =COMPS!F10 -> 20291 | E18: =COMPS!E10 -> 181891.68 | F18: 0.3 | G18: =D18/E18 -> 0.1115554 | H18: =D18/(D18+E18) -> 0.10035973 | I18: 0.77 | J18: =I18/(1+(1-F18)*G18) -> 0.71422689
B19: Tech Mahindra | C19: India | D19: =COMPS!F11 -> 2186.2 | E19: =COMPS!E11 -> 161841.4 | F19: 0.3 | G19: =D19/E19 -> 0.013508287 | H19: =D19/(D19+E19) -> 0.013328245 | I19: 0.805 | J19: =I19/(1+(1-F19)*G19) -> 0.79745938
E21: Average | F21: =AVERAGE(F15:F19) -> 0.3 | G21: =AVERAGE(G15:G19) -> 0.034313608 | H21: =AVERAGE(H15:H19) -> 0.031892767 | I21: =AVERAGE(I15:I19) -> 0.8572 | J21: =AVERAGE(J15:J19) -> 0.83880071
E22: Median | F22: =MEDIAN(F15:F19) -> 0.3 | G22: =MEDIAN(G15:G19) -> 0.014267987 | H22: =MEDIAN(H15:H19) -> 0.014067276 | I22: =MEDIAN(I15:I19) -> 0.805 | J22: =MEDIAN(J15:J19) -> 0.79745938
B25: Cost of Debt | H25: Cost of Equity
B27: Pre Tax Cost of Debt | E27: =416/8737 -> 0.047613597 | H27: Risk Free Return | J27: 0.0683
B28: Tax Rate | E28: =F16 -> 0.3 | H28: Equity Risk Premium | J28: =RM!F10-WACC!J27 -> 0.090581481
B29: Post Tax Cost of Debt | E29: =E27*(1-E28) -> 0.033329518 | H29: Levered Beta 4 | J29: =J38 -> 0.81584911
H30: Cost of Equity | J30: =J27+J28*J29 -> 0.14220082
B33: Capital Structure | H33: Levered Beta
D35: Current | E35: Target | H35: Comps Median Unlevered Beta | J35: =J22 -> 0.79745938
B36: Total Debt | C36: =D16 -> 8737 | D36: =C36/$C$38 -> 0.01869741 | E36: =H21 -> 0.031892767 | H36: Target Debt/Equity | J36: =E40 -> 0.032943424
B37: Market Capitalisation | C37: =E16 -> 458546.98 | D37: =C37/$C$38 -> 0.98130259 | E37: =E38-E36 -> 0.96810723 | H37: Tax Rate | J37: =E28 -> 0.3
B38: Total Capital | C38: =SUM(C36:C37) -> 467283.98 | D38: =C38/$C$38 -> 1 | E38: =D38 -> 1 | H38: Levered Beta | J38: =J35*(1+(1-J37)*J36) -> 0.81584911
B40: Debt/Equity | D40: =D36/D37 -> 0.019053664 | E40: =E36/E37 -> 0.032943424
H43: Weighted Average Cost of Capital
H45: Cost of Equity | J45: =J30 -> 0.14220082
H46: Equity Weight | J46: =E37 -> 0.96810723
H48: Cost of Debt | J48: =E29 -> 0.033329518
H49: Debt Weight | J49: =E36 -> 0.031892767
H51: WACC | J51: =(J45*J46)+(J48*J49) -> 0.13872861

Sheet Raw FS
B4: Particulars | C4: 42064 | D4: 42430 | E4: 42795 | F4: 43160 | G4: 43525 | H4: 43891 | I4: 44256 | J4: 44621 | K4: 44986 | L4: 45352 | M4: 45717 | N4: 46082
B6: Equity Capital | C6: 572 | D6: 1144 | E6: 1144 | F6: 1088 | G6: 2170 | H6: 2122 | I6: 2124 | J6: 2098 | K6: 2069 | L6: 2071 | M6: 2073 | N6: 2024
B7: Reserves | C7: 50164 | D7: 60600 | E7: 67838 | F7: 63835 | G7: 62778 | H7: 63328 | I7: 74227 | J7: 73252 | K7: 73338 | L7: 86045 | M7: 93745 | N7: 90828
B8: Borrowings - | C8: 0 | D8: 0 | E8: 0 | F8: 0 | G8: 0 | H8: 4633 | I8: 5325 | J8: 5474 | K8: 8299 | L8: 8359 | M8: 8227 | N8: 9176
B9: Lease Liabilities | C9: 0 | D9: 0 | E9: 0 | F9: 0 | G9: 0 | H9: 4633 | I9: 5325 | J9: 5474 | K9: 8299 | L9: 8359 | M9: 8227 | N9: 9176
B10: Other Liabilities -
B11: Non controlling int | C11: 0 | D11: 0 | E11: 0 | F11: 1 | G11: 58 | H11: 394 | I11: 431 | J11: 386 | K11: 388 | L11: 345 | M11: 385 | N11: 445
B12: Trade Payables | C12: 140 | D12: 386 | E12: 367 | F12: 694 | G12: 1655 | H12: 2852 | I12: 2645 | J12: 4134 | K12: 3865 | L12: 3956 | M12: 4164 | N12: 4744
B13: Advance from Customers | C13: 27 | D13: 28 | E13: 0 | F13: 0 | G13: 0 | H13: 0 | I13: 0 | J13: 0 | K13: 0 | L13: 0 | M13: 0 | N13: 0
B14: Other liability items | C14: 15386 | D14: 12940 | E14: 13799 | F14: 13731 | G14: 17405 | H14: 18471 | I14: 22759 | J14: 31385 | K14: 36637 | L14: 35244 | M14: 39201 | N14: 47071
B15: Total Liabilities | C15: 66289 | D15: 75098 | E15: 83148 | F15: 79349 | G15: 84066 | H15: 91800 | I15: 107511 | J15: 116729 | K15: 124596 | L15: 136020 | M15: 147795 | N15: 154288
B17: Fixed Assets -
B18: Land | C18: 1564 | D18: 1622 | E18: 1095 | F18: 1229 | G18: 1307 | H18: 1950 | I18: 2035 | J18: 2066 | K18: 2054 | L18: 2037 | M18: 2079 | N18: 1990
B19: Building | C19: 6102 | D19: 6325 | E19: 8419 | F19: 9334 | G19: 10270 | H19: 15104 | I19: 16394 | J19: 16760 | K19: 16903 | L19: 16515 | M19: 16376 | N19: 17193
B20: Plant Machinery | C20: 1427 | D20: 1759 | E20: 2048 | F20: 2306 | G20: 2709 | H20: 3185 | I20: 3296 | J20: 3210 | K20: 3302 | L20: 3428 | M20: 3461 | N20: 3714
B21: Equipments | C21: 676 | D21: 839 | E21: 922 | F21: 1002 | G21: 1101 | H21: 1265 | I21: 1371 | J21: 1427 | K21: 1482 | L21: 1528 | M21: 1628 | N21: 1732
B22: Computers | C22: 3347 | D22: 4486 | E22: 4945 | F22: 4903 | G22: 6287 | H22: 7423 | I22: 8732 | J22: 9936 | K22: 11898 | L22: 12353 | M22: 12925 | N22: 13600
B23: Furniture n fittings | C23: 958 | D23: 1444 | E23: 1277 | F23: 1393 | G23: 1620 | H23: 2073 | I23: 2149 | J23: 2278 | K23: 2303 | L23: 2326 | M23: 2340 | N23: 2438
B24: Vehicles | C24: 34 | D24: 29 | E24: 31 | F24: 31 | G24: 38 | H24: 69 | I24: 73 | J24: 71 | K24: 60 | L24: 62 | M24: 72 | N24: 70
B25: Intangible Assets | C25: 3637 | D25: 3858 | E25: 3743 | F25: 2237 | G25: 3640 | H25: 5528 | I25: 6373 | J25: 6495 | K25: 7594 | L25: 7652 | M25: 10626 | N25: 12729
B26: Other fixed assets | C26: 71 | D26: 931 | E26: 899 | F26: 545 | G26: 1093 | H26: 2289 | I26: 2730 | J26: 2766 | K26: 3281 | L26: 3294 | M26: 5184 | N26: 6296
B27: Gross Block | C27: 17816 | D27: 21293 | E27: 23379 | F27: 22980 | G27: 28065 | H27: 38886 | I27: 43153 | J27: 45009 | K27: 48877 | L27: 49195 | M27: 54691 | N27: 59762
B28: Accumulated Depreciation | C28: 6470 | D28: 7907 | E28: 9200 | F28: 10406 | G28: 12355 | H28: 15097 | I28: 17648 | J28: 19209 | K28: 19652 | L28: 21573 | M28: 23730 | N28: 25992
B29: Net Block | C29: =C27-C28 -> 11346 | D29: =D27-D28 -> 13386 | E29: =E27-E28 -> 14179 | F29: =F27-F28 -> 12574 | G29: =G27-G28 -> 15710 | H29: =H27-H28 -> 23789 | I29: =I27-I28 -> 25505 | J29: =J27-J28 -> 25800 | ... N29: =N27-N28 -> 33770
B30: CWIP | C30: 776 | D30: 960 | E30: 1365 | F30: 1606 | G30: 1388 | H30: 954 | I30: 922 | J30: 416 | K30: 288 | L30: 293 | M30: 814 | N30: 526
B31: Investments | C31: 2270 | D31: 1892 | E31: 16423 | F31: 12163 | G31: 11261 | H31: 8792 | I31: 14205 | J31: 20324 | K31: 19478 | L31: 24623 | M31: 23541 | N31: 21880
B32: Other Assets -
B33: Trade receivables | C33: 9713 | D33: 11330 | E33: 12322 | F33: 13142 | G33: 14827 | H33: 18487 | I33: 19294 | J33: 22698 | K33: 25424 | L33: 30193 | M33: 31158 | N33: 35234
B34: Cash Equivalents | C34: 30367 | D34: 32697 | E34: 22625 | F34: 19818 | G34: 19568 | H34: 18649 | I34: 24714 | J34: 17472 | K34: 12173 | L34: 14786 | M34: 24455 | N34: 22201
B35: Loans n Advances | C35: 399 | D35: 614 | E35: 844 | F35: 830 | G35: 1524 | H35: 1359 | I35: 1460 | J35: 2491 | K35: 3242 | L35: 10330 | M35: 6717 | N35: 6808
B36: Other asset items | C36: 11418 | D36: 14219 | E36: 15390 | F36: 19216 | G36: 19788 | H36: 19770 | I36: 21411 | J36: 27528 | K36: 34766 | L36: 28173 | M36: 30149 | N36: 33869
B37: Total Assets | C37: 66289 | D37: 75098 | E37: 83148 | F37: 79349 | G37: 84066 | H37: 91800 | I37: 107511 | J37: 116729 | K37: 124596 | L37: 136020 | M37: 147795 | N37: 154288
B41: Cash from Operating Activity - | C41: 8353 | D41: 10028 | E41: 11531 | F41: 13218 | G41: 14841 | H41: 17003 | I41: 23224 | J41: 23885 | K41: 22467 | L41: 25210 | M41: 35694 | N41: 33986
B42: Profit from operations | C42: 15946 | D42: 17839 | E42: 19340 | F42: 19963 | G42: 22126 | H42: 23920 | I42: 28845 | J42: 32921 | K42: 37605 | L42: 39523 | M42: 41591 | N42: 45273
B43: Receivables | C43: -1475 | D43: -1654 | E43: -1743 | F43: -1523 | G43: -2881 | H43: -3861 | I43: -1835 | J43: -7937 | K43: -7076 | L43: -2667 | M43: -1769 | N43: -5177
B44: Payables | C44: 0 | D44: 242 | E44: -19 | F44: 328 | G44: 916 | H44: -373 | I44: -245 | J44: 1489 | K44: -279 | L44: 91 | M44: 176 | N44: -26
B45: Loans Advances | C45: -221 | D45: -1134 | E45: 0 | F45: 0 | G45: 0 | H45: 0 | I45: -534 | J45: -1914 | K45: -3108 | L45: -1172 | M45: -1024 | N45: -2645
B46: Other WC items | C46: 854 | D46: 600 | E46: -394 | F46: 1279 | G46: 1512 | H46: 1867 | I46: 3382 | J46: 6938 | K46: 4119 | L46: -1334 | M46: 2322 | N46: 5209
B47: Working capital changes | C47: -842 | D47: -1946 | E47: -2156 | F47: 84 | G47: -453 | H47: -2367 | I47: 768 | J47: -1424 | K47: -6344 | L47: -5082 | M47: -295 | N47: -2639
... B64: Net Cash Flow | C64: 4417 | D64: 2330 | E64: -10072 | F64: -2754 | G64: -303 | H64: -919 | I64: 6065 | J64: -7242 | K64: -5299 | L64: 2613 | M64: 9669 | N64: -2254

Sheet Intrinsic Growth
B5: Calculation of ROIC | C5: ='Raw FS'!J$4 -> 44621 | D5: ='Raw FS'!K$4 -> 44986 | E5: ='Raw FS'!L$4 -> 45352 | F5: ='Raw FS'!M$4 -> 45717 | G5: ='Raw FS'!N$4 -> 46082
B7: Current Assets
B8: ='Raw FS'!B33 -> Trade receivables | C8: ='Raw FS'!J33 -> 22698 | D8: ='Raw FS'!K33 -> 25424 | E8: ='Raw FS'!L33 -> 30193 | F8: ='Raw FS'!M33 -> 31158 | G8: ='Raw FS'!N33 -> 35234
B9: {='Raw FS'!B35:B36} -> Loans n Advances | C9: ='Raw FS'!J35 -> 2491 | D9: ='Raw FS'!K35 -> 3242 | E9: ='Raw FS'!L35 -> 10330 | F9: ='Raw FS'!M35 -> 6717 | G9: ='Raw FS'!N35 -> 6808
B10: Other asset items | C10: ='Raw FS'!J36 -> 27528 | D10: ='Raw FS'!K36 -> 34766 | E10: ='Raw FS'!L36 -> 28173 | F10: ='Raw FS'!M36 -> 30149 | G10: ='Raw FS'!N36 -> 33869
B11: Total Current Assets | C11: =SUM(C8:C10) -> 52717 | D11: =SUM(D8:D10) -> 63432 | E11: =SUM(E8:E10) -> 68696 | F11: =SUM(F8:F10) -> 68024 | G11: =SUM(G8:G10) -> 75911
B13: Current Liabilities
B14: {='Raw FS'!B12:B14} -> Trade Payables | C14: ='Raw FS'!J12 -> 4134 | D14: ='Raw FS'!K12 -> 3865 | E14: ='Raw FS'!L12 -> 3956 | F14: ='Raw FS'!M12 -> 4164 | G14: ='Raw FS'!N12 -> 4744
B15: Advance from Customers | C15: ='Raw FS'!J13 -> 0 | D15: ='Raw FS'!K13 -> 0 | E15: ='Raw FS'!L13 -> 0 | F15: ='Raw FS'!M13 -> 0 | G15: ='Raw FS'!N13 -> 0
B16: Other liability items | C16: ='Raw FS'!J14 -> 31385 | D16: ='Raw FS'!K14 -> 36637 | E16: ='Raw FS'!L14 -> 35244 | F16: ='Raw FS'!M14 -> 39201 | G16: ='Raw FS'!N14 -> 47071
B17: Total Current Liabilities | C17: =SUM(C14:C16) -> 35519 | D17: =SUM(D14:D16) -> 40502 | E17: =SUM(E14:E16) -> 39200 | F17: =SUM(F14:F16) -> 43365 | G17: =SUM(G14:G16) -> 51815
A19: # | B19: Net Working Capital | C19: =C11-C17 -> 17198 | D19: =D11-D17 -> 22930 | E19: =E11-E17 -> 29496 | F19: =F11-F17 -> 24659 | G19: =G11-G17 -> 24096
B21: Non Current Assets
B22: {='Raw FS'!B18:B26} -> Land | C22: ='Raw FS'!J18 -> 2066 | D22: ='Raw FS'!K18 -> 2054 | E22: ='Raw FS'!L18 -> 2037 | F22: ='Raw FS'!M18 -> 2079 | G22: ='Raw FS'!N18 -> 1990
B23: Building | C23: ='Raw FS'!J19 -> 16760 | D23: ='Raw FS'!K19 -> 16903 | E23: ='Raw FS'!L19 -> 16515 | F23: ='Raw FS'!M19 -> 16376 | G23: ='Raw FS'!N19 -> 17193
B24: Plant Machinery | C24: ='Raw FS'!J20 -> 3210 | D24: ='Raw FS'!K20 -> 3302 | E24: ='Raw FS'!L20 -> 3428 | F24: ='Raw FS'!M20 -> 3461 | G24: ='Raw FS'!N20 -> 3714
B25: Equipments | C25: ='Raw FS'!J21 -> 1427 | D25: ='Raw FS'!K21 -> 1482 | E25: ='Raw FS'!L21 -> 1528 | F25: ='Raw FS'!M21 -> 1628 | G25: ='Raw FS'!N21 -> 1732
B26: Computers | C26: ='Raw FS'!J22 -> 9936 | D26: ='Raw FS'!K22 -> 11898 | E26: ='Raw FS'!L22 -> 12353 | F26: ='Raw FS'!M22 -> 12925 | G26: ='Raw FS'!N22 -> 13600
B27: Furniture n fittings | C27: ='Raw FS'!J23 -> 2278 | D27: ='Raw FS'!K23 -> 2303 | E27: ='Raw FS'!L23 -> 2326 | F27: ='Raw FS'!M23 -> 2340 | G27: ='Raw FS'!N23 -> 2438
B28: Vehicles | C28: ='Raw FS'!J24 -> 71 | D28: ='Raw FS'!K24 -> 60 | E28: ='Raw FS'!L24 -> 62 | F28: ='Raw FS'!M24 -> 72 | G28: ='Raw FS'!N24 -> 70
B29: Intangible Assets | C29: ='Raw FS'!J25 -> 6495 | D29: ='Raw FS'!K25 -> 7594 | E29: ='Raw FS'!L25 -> 7652 | F29: ='Raw FS'!M25 -> 10626 | G29: ='Raw FS'!N25 -> 12729
B30: Other fixed assets | C30: ='Raw FS'!J26 -> 2766 | D30: ='Raw FS'!K26 -> 3281 | E30: ='Raw FS'!L26 -> 3294 | F30: ='Raw FS'!M26 -> 5184 | G30: ='Raw FS'!N26 -> 6296
B31: Gross Block | C31: =SUM(C22:C30) -> 45009 | D31: =SUM(D22:D30) -> 48877 | E31: =SUM(E22:E30) -> 49195 | F31: =SUM(F22:F30) -> 54691 | G31: =SUM(G22:G30) -> 59762
B32: Accumulated Depreciation | C32: =-'Raw FS'!J28 -> -19209 | D32: =-'Raw FS'!K28 -> -19652 | E32: =-'Raw FS'!L28 -> -21573 | F32: =-'Raw FS'!M28 -> -23730 | G32: =-'Raw FS'!N28 -> -25992
B33: Net Non Current Assets | C33: =SUM(C31:C32) -> 25800 | D33: =SUM(D31:D32) -> 29225 | E33: =SUM(E31:E32) -> 27622 | F33: =SUM(F31:F32) -> 30961 | G33: =SUM(G31:G32) -> 33770
A35: # | B35: Invested Capital | C35: =C33+C19 -> 42998 | D35: =D33+D19 -> 52155 | E35: =E33+E19 -> 57118 | F35: =F33+F19 -> 55620 | G35: =G33+G19 -> 57866
B36: EBIT | C36: =HistoricalFS!H17-HistoricalFS!H23 -> 28015 | D36: =HistoricalFS!I17-HistoricalFS!I23 -> 30905 | E36: =HistoricalFS!J17-HistoricalFS!J23 -> 31747 | F36: =HistoricalFS!K17-HistoricalFS!K23 -> 34424 | G36: =HistoricalFS!L17-HistoricalFS!L23 -> 37378
A38: # | B38: ROIC | C38: =C36/C35 -> 0.65154193 | D38: =D36/D35 -> 0.59256064 | E38: =E36/E35 -> 0.55581428 | F38: =F36/F35 -> 0.61891406 | G38: =G36/G35 -> 0.64594062
B40: Calculation of Reinvestment | C40: ='Raw FS'!J$4 -> 44621 | D40: ='Raw FS'!K$4 -> 44986 | E40: ='Raw FS'!L$4 -> 45352 | F40: ='Raw FS'!M$4 -> 45717 | G40: ='Raw FS'!N$4 -> 46082
B42: Net Capex | C42: =-'Raw FS'!J50 -> 2161 | D42: =-'Raw FS'!K50 -> 2579 | E42: =-'Raw FS'!L50 -> 2201 | F42: =-'Raw FS'!M50 -> 2237 | G42: =-'Raw FS'!N50 -> 2727
B43: Changes in Working Capital | D43: =D19-C19 -> 5732 | E43: =E19-D19 -> 6566 | F43: =F19-E19 -> -4837 | G43: =G19-F19 -> -563
B45: EBIT | C45: =C36 -> 28015 | D45: =D36 -> 30905 | E45: =E36 -> 31747 | F45: =F36 -> 34424 | G45: =G36 -> 37378
B46: Marginal Tax Rate | C46: =HistoricalFS!H30 -> 0.26449684 | D46: =HistoricalFS!I30 -> 0.27651401 | E46: =HistoricalFS!J30 -> 0.27064577 | F46: =HistoricalFS!K30 -> 0.28871517 | G46: =HistoricalFS!L30 -> 0.26305788
B47: EBIT(1-T) | C47: =C45*(1-C46) -> 20605.121 | D47: =D45*(1-D46) -> 22359.334 | E47: =E45*(1-E46) -> 23154.809 | F47: =F45*(1-F46) -> 24485.269 | G47: =G45*(1-G46) -> 27545.422
B49: Reinvestment | D49: =SUM(D42:D43) -> 8311 | E49: =SUM(E42:E43) -> 8767 | F49: =SUM(F42:F43) -> -2600 | G49: =SUM(G42:G43) -> 2164
B51: Reinvestment Rate | D51: =D49/D47 -> 0.37170158 | E51: =E49/E47 -> 0.37862546 | F51: =F49/F47 -> -0.10618629 | G51: =G49/G47 -> 0.078561148
F53: 4 Year Average | G53: =AVERAGE(D51:G51) -> 0.18067547
F54: 4 Year Median | G54: =MEDIAN(D51:G51) -> 0.22513137
B56: Calculation of Growth Rate | C56: ='Raw FS'!J$4 -> 44621 | D56: ='Raw FS'!K$4 -> 44986 | E56: ='Raw FS'!L$4 -> 45352 | F56: ='Raw FS'!M$4 -> 45717 | G56: ='Raw FS'!N$4 -> 46082
B58: Reinvestment Rate | D58: =D51 -> 0.37170158 | E58: =E51 -> 0.37862546 | F58: =F51 -> -0.10618629 | G58: =G51 -> 0.078561148
...

Sheet DCF
B5: Calculaton of PV of FCFF | E5: ='Raw FS'!N$4 -> 46082 | F5: =E5+366 -> 46448 | G5: =F5+365 -> 46813 | H5: =G5+365 -> 47178 | I5: =H5+365 -> 47543 | J5: =I5+365 -> 47908
B7: EBIT | E7: =HistoricalFS!L17-HistoricalFS!L23 -> 37378 | F7: =E7*(1+$C$16) -> 42259.404 | G7: =F7*(1+$C$16) -> 47778.297 | H7: =G7*(1+$C$16) -> 54017.934 | I7: =H7*(1+$C$16) -> 61072.441 | J7: =I7*(1+$C$16) -> 69048.235
B8: Tax Rate | E8: =HistoricalFS!L30 -> 0.26305788 | F8: =Assumptions!$C$5 -> 0.27268594 | G8: =Assumptions!$C$5 -> 0.27268594 | H8: =Assumptions!$C$5 -> 0.27268594 | I8: =Assumptions!$C$5 -> 0.27268594 | J8: =Assumptions!$C$5 -> 0.27268594
B9: EBIT(1-T) | E9: =E7*(1-E8) -> 27545.422 | F9: =F7*(1-F8) -> 30735.859 | G9: =G7*(1-G8) -> 34749.828 | H9: =H7*(1-H8) -> 39288.003 | I9: =I7*(1-I8) -> 44418.845 | J9: =J7*(1-J8) -> 50219.753
B10: Less:Reinvestment Rate | E10: ='Intrinsic Growth'!G54 -> 0.22513137 | F10: =E10+(($J$10-$E$10)/4) -> 0.23134852 | G10: =F10+(($J$10-$E$10)/4) -> 0.23756568 | H10: =G10+(($J$10-$E$10)/4) -> 0.24378284 | I10: =H10+(($J$10-$E$10)/4) -> 0.25 | J10: 0.25
B11: FCFF | E11: =E9*(1-E10) -> 21344.084 | F11: =F9*(1-F10) -> 23625.163 | G11: =G9*(1-G10) -> 26494.461 | H11: =H9*(1-H10) -> 29710.262 | I11: =I9*(1-I10) -> 33314.134 | J11: =J9*(1-J10) -> 37664.814
B12: Mid Year Convention | F12: 0.5 | G12: =F12+1 -> 1.5 | H12: =G12+1 -> 2.5 | I12: =H12+1 -> 3.5 | J12: =I12+1 -> 4.5
B13: Discounting Factor | F13: =1/(1+$C$18)^F12 -> 0.93710851 | G13: =1/(1+$C$18)^G12 -> 0.8229428 | H13: =1/(1+$C$18)^H12 -> 0.72268562 | I13: =1/(1+$C$18)^I12 -> 0.63464254 | J13: =1/(1+$C$18)^J12 -> 0.55732554
B14: PV of FCFF | F14: =F11*F13 -> 22139.341 | G14: =G11*G13 -> 21803.426 | H14: =H11*H13 -> 21471.179 | I14: =I11*I13 -> 21142.567 | J14: =J11*J13 -> 20991.563
B16: Expected Growth Rate | C16: ='Intrinsic Growth'!G64 -> 0.13059564
B17: Terminal Growth | C17: 0.04
B18: WACC | C18: =WACC!J51 -> 0.13872861
B20: Calculation of Terminal Value | E20: Sensitivity Analysis
E21: =C32 -> 328671.67 | F21: 0.1 | G21: 0.12 | H21: 0.1387 | I21: 0.15 | J21: 0.18
B22: FCFF (n+1) | C22: =J11*(1+C17) -> 39171.407 | E22: 0.03 | F22: 419422.73 | G22: 350117.25 | H22: 308387.32 | I22: 289474.96 | J22: 253089.58
B23: WACC | C23: =C18 -> 0.13872861 | E23: 0.04 | F23: 471401.84 | G23: 380438.4 | H23: 328735.77 | I23: 306013.76 | J23: 263485.4
B24: Terminal Growth Rate | C24: =C17 -> 0.04 | E24: 0.05 | F24: 544172.59 | G24: 419422.73 | H24: 353672.38 | I24: 325860.33 | J24: 275480.58
E25: 0.06 | F25: 653328.72 | G25: 471401.84 | H25: 384946.12 | I25: 350117.25 | J25: 289474.96
B26: Terminal Value | C26: =C22/(C23-C24) -> 396758.4 | E26: 0.07 | F26: 835255.6 | G26: 544172.59 | H26: 425324.29 | I26: 380438.4 | J26: 306013.76
B28: Calculation of Equity Value | E28: Sensitivity Analysis
E29: =C39 -> 842.00174 | F29: 0.12 | G29: 0.125 | H29: 0.13 | I29: 0.1387 | J29: 0.15
B30: PV of FCFF | C30: =SUM(F14:J14) -> 107548.08 | E30: 0.03 | F30: 894.84749 | G30: 863.38782 | H30: 835.07411 | I30: 792.01747 | J30: 745.41403
B31: PV of Terminal Value | C31: =C26*J13 -> 221123.59 | E31: 0.035 | F31: 930.00831 | G31: 894.84749 | H31: 863.38782 | I31: 815.87976 | J31: 764.90535
B32: Value of operating Asset | C32: =SUM(C30:C31) -> 328671.67 | E32: 0.04 | F32: 969.56422 | G32: 930.00831 | H32: 894.84749 | I32: 842.15971 | J32: 786.16861
E33: 0.045 | F33: 1014.3943 | G33: 969.56422 | H33: 930.00831 | I33: 871.24434 | J33: 809.45694
B34: Add:Cash | C34: ='Data Sheet'!K69 -> 22201 | E34: 0.05 | F34: 1065.6286 | G34: 1014.3943 | H34: 969.56422 | I34: 903.60797 | J34: 835.07411
B35: Less:Debt | C35: ='Raw FS'!N8 -> 9176
B36: Value of Equity | C36: =C32+C34-C35 -> 341696.67
B37: No. of Shares | C37: ='Data Sheet'!B6 -> 405.81468
B39: Equity Value Per Share | C39: =C36/C37 -> 842.00174
B41: Share Price | C41: 1175
B42: Discount/Premium | C42: =C41/C39-1 -> 0.39548406

Sheet Assumptions
B5: Normalised Tax Rate | C5: =AVERAGE(HistoricalFS!H30:L30) -> 0.27268594

Sheet RM
B5: Return on Market
B7: Year | C7: Annual
B8: 2000 | C8: -0.1465 | E8: Average Return | F8: =AVERAGE(C8:C34) -> 0.14588148
B9: 2001 | C9: -0.1618 | E9: Dividend Yield | F9: 0.013
B10: 2002 | C10: 0.0325 | E10: Total Market Returns | F10: =SUM(F8:F9) -> 0.15888148
B11: 2003 | C11: 0.719
B12: 2004 | C12: 0.1068
B13: 2005 | C13: 0.3634
B14: 2006 | C14: 0.3983
B15: 2007 | C15: 0.5477
B16: 2008 | C16: -0.5179
B17: 2009 | C17: 0.7576
B18: 2010 | C18: 0.1795
B19: 2011 | C19: -0.2462
